<?xml version="1.0"?>
<robot name="gripper">

  <link name="base_link">
    <visual>
      <geometry>
        <mesh filename="package://wezelROS/description/meshes/base.stl"/>
      </geometry>
      <origin xyz="0 0 0" rpy="1.57 0 3.14"/>
    </visual>
  </link>

  <link name="rotator_link1">
    <visual>
      <geometry>
        <mesh filename="package://wezelROS/description/meshes/finger_rotator.stl"/>
      </geometry>
      <origin xyz="0 0 0" rpy="1.57 0 0"/>
    </visual>
  </link>

  <link name="rotator_link2">
    <visual>
      <geometry>
        <mesh filename="package://wezelROS/description/meshes/finger_rotator.stl"/>
      </geometry>
      <origin xyz="0 0 0" rpy="1.57 0 3.14"/>
    </visual>
  </link>

  <link name="rotator_link3">
    <visual>
      <geometry>
        <mesh filename="package://wezelROS/description/meshes/finger_rotator.stl"/>
      </geometry>
      <origin xyz="0 0 0" rpy="1.57 0 3.14"/>
    </visual>
  </link>

  <link name="finger_link1">
    <visual>
      <geometry>
        <mesh filename="package://wezelROS/description/meshes/finger.stl"/>
      </geometry>
      <origin xyz="0 0 0" rpy="1.57 0 0"/>
    </visual>
  </link>

  <link name="finger_link2">
    <visual>
      <geometry>
        <mesh filename="package://wezelROS/description/meshes/finger.stl"/>
      </geometry>
      <origin xyz="0 0 0" rpy="1.57 0 3.14"/>
    </visual>
  </link>
  
  <link name="finger_link3">
    <visual>
      <geometry>
        <mesh filename="package://wezelROS/description/meshes/finger.stl"/>
      </geometry>
      <origin xyz="0 0 0" rpy="1.57 0 3.14"/>
    </visual>
  </link>

  <joint name="rotator1" type="fixed">
    <parent link="base_link"/>
    <child link="rotator_link1"/>
    <axis xyz="0 0 1"/>
    <origin xyz="0 0.04 0.021352"/>
  </joint>

  <joint name="rotator2" type="continuous">
    <parent link="base_link"/>
    <child link="rotator_link2"/>
    <axis xyz="0 0 1"/>
    <origin xyz="0.026 -0.030397 0.021352" rpy="0 0 0.1185"/>
    <limit lower="-1.57" upper="1.57" effort="30" velocity="5"/>
  </joint>

  <joint name="rotator3" type="continuous">
    <parent link="base_link"/>
    <child link="rotator_link3"/>
    <axis xyz="0 0 1"/>
    <origin xyz="-0.026 -0.030397 0.021352" rpy="0 0 -0.1185"/>
    <limit lower="-1.57" upper="1.57" effort="30" velocity="5"/>
    <mimic joint="rotator2" multiplier="-1"/>
  </joint>

  <joint name="finger1" type="revolute">
    <parent link="rotator_link1"/>
    <child link="finger_link1"/>
    <axis xyz="1 0 0"/>
    <origin xyz="0 0 0"/>
    <limit lower="-1" upper="1.57" effort="30" velocity="5"/>
  </joint>

  <joint name="finger2" type="revolute">
    <parent link="rotator_link2"/>
    <child link="finger_link2"/>
    <axis xyz="1 0 0"/>
    <origin xyz="0 0 0"/>
    <limit lower="-1.57" upper="1" effort="30" velocity="5"/>
  </joint>

  <joint name="finger3" type="revolute">
    <parent link="rotator_link3"/>
    <child link="finger_link3"/>
    <axis xyz="1 0 0"/>
    <origin xyz="0 0 0"/>
    <limit lower="-1.57" upper="1" effort="30" velocity="5"/>
  </joint>

</robot>
